2025-06-26 01:36:26,965 - discord.client - INFO - logging in using static token
2025-06-26 01:36:29,478 - discord.gateway - INFO - Shard ID None has connected to Gateway (Session ID: a2c480a3912a48c4533696aa157c3eef).
2025-06-26 01:37:50,127 - discord.client - INFO - logging in using static token
2025-06-26 01:37:52,885 - discord.gateway - INFO - Shard ID None has connected to Gateway (Session ID: 295888487dd75896b982cce248114700).
2025-06-26 02:55:33,029 - discord.client - INFO - logging in using static token
2025-06-26 02:55:35,319 - discord.gateway - INFO - Shard ID None has connected to Gateway (Session ID: b18deeb1a8c218c594b5805505233e5c).
2025-06-26 04:23:24,193 - discord.client - ERROR - Attempting a reconnect in 0.87s
Traceback (most recent call last):
  File "C:\Users\daksh\AppData\Local\Programs\Python\Python313\Lib\site-packages\aiohttp\connector.py", line 1376, in _create_direct_connection
    hosts = await self._resolve_host(host, port, traces=traces)
            ^^^^^^^^^^^^^^^^^^^^^^^^^^^^^^^^^^^^^^^^^^^^^^^^^^^
  File "C:\Users\daksh\AppData\Local\Programs\Python\Python313\Lib\site-packages\aiohttp\connector.py", line 1013, in _resolve_host
    return await asyncio.shield(resolved_host_task)
           ^^^^^^^^^^^^^^^^^^^^^^^^^^^^^^^^^^^^^^^^
  File "C:\Users\daksh\AppData\Local\Programs\Python\Python313\Lib\site-packages\aiohttp\connector.py", line 1044, in _resolve_host_with_throttle
    addrs = await self._resolver.resolve(host, port, family=self._family)
            ^^^^^^^^^^^^^^^^^^^^^^^^^^^^^^^^^^^^^^^^^^^^^^^^^^^^^^^^^^^^^
  File "C:\Users\daksh\AppData\Local\Programs\Python\Python313\Lib\site-packages\aiohttp\resolver.py", line 40, in resolve
    infos = await self._loop.getaddrinfo(
            ^^^^^^^^^^^^^^^^^^^^^^^^^^^^^
    ...<5 lines>...
    )
    ^
  File "C:\Users\daksh\AppData\Local\Programs\Python\Python313\Lib\asyncio\base_events.py", line 933, in getaddrinfo
    return await self.run_in_executor(
           ^^^^^^^^^^^^^^^^^^^^^^^^^^^
        None, getaddr_func, host, port, family, type, proto, flags)
        ^^^^^^^^^^^^^^^^^^^^^^^^^^^^^^^^^^^^^^^^^^^^^^^^^^^^^^^^^^^
  File "C:\Users\daksh\AppData\Local\Programs\Python\Python313\Lib\concurrent\futures\thread.py", line 59, in run
    result = self.fn(*self.args, **self.kwargs)
  File "C:\Users\daksh\AppData\Local\Programs\Python\Python313\Lib\socket.py", line 977, in getaddrinfo
    for res in _socket.getaddrinfo(host, port, family, type, proto, flags):
               ~~~~~~~~~~~~~~~~~~~^^^^^^^^^^^^^^^^^^^^^^^^^^^^^^^^^^^^^^^^
socket.gaierror: [Errno 11001] getaddrinfo failed

The above exception was the direct cause of the following exception:

Traceback (most recent call last):
  File "C:\Users\daksh\AppData\Local\Programs\Python\Python313\Lib\site-packages\discord\client.py", line 701, in connect
    self.ws = await asyncio.wait_for(coro, timeout=60.0)
              ^^^^^^^^^^^^^^^^^^^^^^^^^^^^^^^^^^^^^^^^^^
  File "C:\Users\daksh\AppData\Local\Programs\Python\Python313\Lib\asyncio\tasks.py", line 507, in wait_for
    return await fut
           ^^^^^^^^^
  File "C:\Users\daksh\AppData\Local\Programs\Python\Python313\Lib\site-packages\discord\gateway.py", line 375, in from_client
    socket = await client.http.ws_connect(str(url))
             ^^^^^^^^^^^^^^^^^^^^^^^^^^^^^^^^^^^^^^
  File "C:\Users\daksh\AppData\Local\Programs\Python\Python313\Lib\site-packages\discord\http.py", line 554, in ws_connect
    return await self.__session.ws_connect(url, **kwargs)
           ^^^^^^^^^^^^^^^^^^^^^^^^^^^^^^^^^^^^^^^^^^^^^^
  File "C:\Users\daksh\AppData\Local\Programs\Python\Python313\Lib\site-packages\aiohttp\client.py", line 1036, in _ws_connect
    resp = await self.request(
           ^^^^^^^^^^^^^^^^^^^
    ...<11 lines>...
    )
    ^
  File "C:\Users\daksh\AppData\Local\Programs\Python\Python313\Lib\site-packages\aiohttp\client.py", line 760, in _request
    resp = await handler(req)
           ^^^^^^^^^^^^^^^^^^
  File "C:\Users\daksh\AppData\Local\Programs\Python\Python313\Lib\site-packages\aiohttp\client.py", line 715, in _connect_and_send_request
    conn = await self._connector.connect(
           ^^^^^^^^^^^^^^^^^^^^^^^^^^^^^^
        req, traces=traces, timeout=real_timeout
        ^^^^^^^^^^^^^^^^^^^^^^^^^^^^^^^^^^^^^^^^
    )
    ^
  File "C:\Users\daksh\AppData\Local\Programs\Python\Python313\Lib\site-packages\aiohttp\connector.py", line 561, in connect
    proto = await self._create_connection(req, traces, timeout)
            ^^^^^^^^^^^^^^^^^^^^^^^^^^^^^^^^^^^^^^^^^^^^^^^^^^^
  File "C:\Users\daksh\AppData\Local\Programs\Python\Python313\Lib\site-packages\aiohttp\connector.py", line 1074, in _create_connection
    _, proto = await self._create_direct_connection(req, traces, timeout)
               ^^^^^^^^^^^^^^^^^^^^^^^^^^^^^^^^^^^^^^^^^^^^^^^^^^^^^^^^^^
  File "C:\Users\daksh\AppData\Local\Programs\Python\Python313\Lib\site-packages\aiohttp\connector.py", line 1382, in _create_direct_connection
    raise ClientConnectorDNSError(req.connection_key, exc) from exc
aiohttp.client_exceptions.ClientConnectorDNSError: Cannot connect to host gateway-us-east1-c.discord.gg:443 ssl:default [getaddrinfo failed]
2025-06-26 04:23:25,254 - discord.client - ERROR - Attempting a reconnect in 2.46s
Traceback (most recent call last):
  File "C:\Users\daksh\AppData\Local\Programs\Python\Python313\Lib\site-packages\aiohttp\connector.py", line 1376, in _create_direct_connection
    hosts = await self._resolve_host(host, port, traces=traces)
            ^^^^^^^^^^^^^^^^^^^^^^^^^^^^^^^^^^^^^^^^^^^^^^^^^^^
  File "C:\Users\daksh\AppData\Local\Programs\Python\Python313\Lib\site-packages\aiohttp\connector.py", line 1013, in _resolve_host
    return await asyncio.shield(resolved_host_task)
           ^^^^^^^^^^^^^^^^^^^^^^^^^^^^^^^^^^^^^^^^
  File "C:\Users\daksh\AppData\Local\Programs\Python\Python313\Lib\site-packages\aiohttp\connector.py", line 1044, in _resolve_host_with_throttle
    addrs = await self._resolver.resolve(host, port, family=self._family)
            ^^^^^^^^^^^^^^^^^^^^^^^^^^^^^^^^^^^^^^^^^^^^^^^^^^^^^^^^^^^^^
  File "C:\Users\daksh\AppData\Local\Programs\Python\Python313\Lib\site-packages\aiohttp\resolver.py", line 40, in resolve
    infos = await self._loop.getaddrinfo(
            ^^^^^^^^^^^^^^^^^^^^^^^^^^^^^
    ...<5 lines>...
    )
    ^
  File "C:\Users\daksh\AppData\Local\Programs\Python\Python313\Lib\asyncio\base_events.py", line 933, in getaddrinfo
    return await self.run_in_executor(
           ^^^^^^^^^^^^^^^^^^^^^^^^^^^
        None, getaddr_func, host, port, family, type, proto, flags)
        ^^^^^^^^^^^^^^^^^^^^^^^^^^^^^^^^^^^^^^^^^^^^^^^^^^^^^^^^^^^
  File "C:\Users\daksh\AppData\Local\Programs\Python\Python313\Lib\concurrent\futures\thread.py", line 59, in run
    result = self.fn(*self.args, **self.kwargs)
  File "C:\Users\daksh\AppData\Local\Programs\Python\Python313\Lib\socket.py", line 977, in getaddrinfo
    for res in _socket.getaddrinfo(host, port, family, type, proto, flags):
               ~~~~~~~~~~~~~~~~~~~^^^^^^^^^^^^^^^^^^^^^^^^^^^^^^^^^^^^^^^^
socket.gaierror: [Errno 11001] getaddrinfo failed

The above exception was the direct cause of the following exception:

Traceback (most recent call last):
  File "C:\Users\daksh\AppData\Local\Programs\Python\Python313\Lib\site-packages\discord\client.py", line 701, in connect
    self.ws = await asyncio.wait_for(coro, timeout=60.0)
              ^^^^^^^^^^^^^^^^^^^^^^^^^^^^^^^^^^^^^^^^^^
  File "C:\Users\daksh\AppData\Local\Programs\Python\Python313\Lib\asyncio\tasks.py", line 507, in wait_for
    return await fut
           ^^^^^^^^^
  File "C:\Users\daksh\AppData\Local\Programs\Python\Python313\Lib\site-packages\discord\gateway.py", line 375, in from_client
    socket = await client.http.ws_connect(str(url))
             ^^^^^^^^^^^^^^^^^^^^^^^^^^^^^^^^^^^^^^
  File "C:\Users\daksh\AppData\Local\Programs\Python\Python313\Lib\site-packages\discord\http.py", line 554, in ws_connect
    return await self.__session.ws_connect(url, **kwargs)
           ^^^^^^^^^^^^^^^^^^^^^^^^^^^^^^^^^^^^^^^^^^^^^^
  File "C:\Users\daksh\AppData\Local\Programs\Python\Python313\Lib\site-packages\aiohttp\client.py", line 1036, in _ws_connect
    resp = await self.request(
           ^^^^^^^^^^^^^^^^^^^
    ...<11 lines>...
    )
    ^
  File "C:\Users\daksh\AppData\Local\Programs\Python\Python313\Lib\site-packages\aiohttp\client.py", line 760, in _request
    resp = await handler(req)
           ^^^^^^^^^^^^^^^^^^
  File "C:\Users\daksh\AppData\Local\Programs\Python\Python313\Lib\site-packages\aiohttp\client.py", line 715, in _connect_and_send_request
    conn = await self._connector.connect(
           ^^^^^^^^^^^^^^^^^^^^^^^^^^^^^^
        req, traces=traces, timeout=real_timeout
        ^^^^^^^^^^^^^^^^^^^^^^^^^^^^^^^^^^^^^^^^
    )
    ^
  File "C:\Users\daksh\AppData\Local\Programs\Python\Python313\Lib\site-packages\aiohttp\connector.py", line 561, in connect
    proto = await self._create_connection(req, traces, timeout)
            ^^^^^^^^^^^^^^^^^^^^^^^^^^^^^^^^^^^^^^^^^^^^^^^^^^^
  File "C:\Users\daksh\AppData\Local\Programs\Python\Python313\Lib\site-packages\aiohttp\connector.py", line 1074, in _create_connection
    _, proto = await self._create_direct_connection(req, traces, timeout)
               ^^^^^^^^^^^^^^^^^^^^^^^^^^^^^^^^^^^^^^^^^^^^^^^^^^^^^^^^^^
  File "C:\Users\daksh\AppData\Local\Programs\Python\Python313\Lib\site-packages\aiohttp\connector.py", line 1382, in _create_direct_connection
    raise ClientConnectorDNSError(req.connection_key, exc) from exc
aiohttp.client_exceptions.ClientConnectorDNSError: Cannot connect to host gateway-us-east1-c.discord.gg:443 ssl:default [getaddrinfo failed]
2025-06-26 04:23:27,732 - discord.client - ERROR - Attempting a reconnect in 7.82s
Traceback (most recent call last):
  File "C:\Users\daksh\AppData\Local\Programs\Python\Python313\Lib\site-packages\aiohttp\connector.py", line 1376, in _create_direct_connection
    hosts = await self._resolve_host(host, port, traces=traces)
            ^^^^^^^^^^^^^^^^^^^^^^^^^^^^^^^^^^^^^^^^^^^^^^^^^^^
  File "C:\Users\daksh\AppData\Local\Programs\Python\Python313\Lib\site-packages\aiohttp\connector.py", line 1013, in _resolve_host
    return await asyncio.shield(resolved_host_task)
           ^^^^^^^^^^^^^^^^^^^^^^^^^^^^^^^^^^^^^^^^
  File "C:\Users\daksh\AppData\Local\Programs\Python\Python313\Lib\site-packages\aiohttp\connector.py", line 1044, in _resolve_host_with_throttle
    addrs = await self._resolver.resolve(host, port, family=self._family)
            ^^^^^^^^^^^^^^^^^^^^^^^^^^^^^^^^^^^^^^^^^^^^^^^^^^^^^^^^^^^^^
  File "C:\Users\daksh\AppData\Local\Programs\Python\Python313\Lib\site-packages\aiohttp\resolver.py", line 40, in resolve
    infos = await self._loop.getaddrinfo(
            ^^^^^^^^^^^^^^^^^^^^^^^^^^^^^
    ...<5 lines>...
    )
    ^
  File "C:\Users\daksh\AppData\Local\Programs\Python\Python313\Lib\asyncio\base_events.py", line 933, in getaddrinfo
    return await self.run_in_executor(
           ^^^^^^^^^^^^^^^^^^^^^^^^^^^
        None, getaddr_func, host, port, family, type, proto, flags)
        ^^^^^^^^^^^^^^^^^^^^^^^^^^^^^^^^^^^^^^^^^^^^^^^^^^^^^^^^^^^
  File "C:\Users\daksh\AppData\Local\Programs\Python\Python313\Lib\concurrent\futures\thread.py", line 59, in run
    result = self.fn(*self.args, **self.kwargs)
  File "C:\Users\daksh\AppData\Local\Programs\Python\Python313\Lib\socket.py", line 977, in getaddrinfo
    for res in _socket.getaddrinfo(host, port, family, type, proto, flags):
               ~~~~~~~~~~~~~~~~~~~^^^^^^^^^^^^^^^^^^^^^^^^^^^^^^^^^^^^^^^^
socket.gaierror: [Errno 11001] getaddrinfo failed

The above exception was the direct cause of the following exception:

Traceback (most recent call last):
  File "C:\Users\daksh\AppData\Local\Programs\Python\Python313\Lib\site-packages\discord\client.py", line 701, in connect
    self.ws = await asyncio.wait_for(coro, timeout=60.0)
              ^^^^^^^^^^^^^^^^^^^^^^^^^^^^^^^^^^^^^^^^^^
  File "C:\Users\daksh\AppData\Local\Programs\Python\Python313\Lib\asyncio\tasks.py", line 507, in wait_for
    return await fut
           ^^^^^^^^^
  File "C:\Users\daksh\AppData\Local\Programs\Python\Python313\Lib\site-packages\discord\gateway.py", line 375, in from_client
    socket = await client.http.ws_connect(str(url))
             ^^^^^^^^^^^^^^^^^^^^^^^^^^^^^^^^^^^^^^
  File "C:\Users\daksh\AppData\Local\Programs\Python\Python313\Lib\site-packages\discord\http.py", line 554, in ws_connect
    return await self.__session.ws_connect(url, **kwargs)
           ^^^^^^^^^^^^^^^^^^^^^^^^^^^^^^^^^^^^^^^^^^^^^^
  File "C:\Users\daksh\AppData\Local\Programs\Python\Python313\Lib\site-packages\aiohttp\client.py", line 1036, in _ws_connect
    resp = await self.request(
           ^^^^^^^^^^^^^^^^^^^
    ...<11 lines>...
    )
    ^
  File "C:\Users\daksh\AppData\Local\Programs\Python\Python313\Lib\site-packages\aiohttp\client.py", line 760, in _request
    resp = await handler(req)
           ^^^^^^^^^^^^^^^^^^
  File "C:\Users\daksh\AppData\Local\Programs\Python\Python313\Lib\site-packages\aiohttp\client.py", line 715, in _connect_and_send_request
    conn = await self._connector.connect(
           ^^^^^^^^^^^^^^^^^^^^^^^^^^^^^^
        req, traces=traces, timeout=real_timeout
        ^^^^^^^^^^^^^^^^^^^^^^^^^^^^^^^^^^^^^^^^
    )
    ^
  File "C:\Users\daksh\AppData\Local\Programs\Python\Python313\Lib\site-packages\aiohttp\connector.py", line 561, in connect
    proto = await self._create_connection(req, traces, timeout)
            ^^^^^^^^^^^^^^^^^^^^^^^^^^^^^^^^^^^^^^^^^^^^^^^^^^^
  File "C:\Users\daksh\AppData\Local\Programs\Python\Python313\Lib\site-packages\aiohttp\connector.py", line 1074, in _create_connection
    _, proto = await self._create_direct_connection(req, traces, timeout)
               ^^^^^^^^^^^^^^^^^^^^^^^^^^^^^^^^^^^^^^^^^^^^^^^^^^^^^^^^^^
  File "C:\Users\daksh\AppData\Local\Programs\Python\Python313\Lib\site-packages\aiohttp\connector.py", line 1382, in _create_direct_connection
    raise ClientConnectorDNSError(req.connection_key, exc) from exc
aiohttp.client_exceptions.ClientConnectorDNSError: Cannot connect to host gateway-us-east1-c.discord.gg:443 ssl:default [getaddrinfo failed]
2025-06-26 11:32:12,512 - discord.client - ERROR - Attempting a reconnect in 0.21s
Traceback (most recent call last):
  File "C:\Users\daksh\AppData\Local\Programs\Python\Python313\Lib\site-packages\aiohttp\connector.py", line 1376, in _create_direct_connection
    hosts = await self._resolve_host(host, port, traces=traces)
            ^^^^^^^^^^^^^^^^^^^^^^^^^^^^^^^^^^^^^^^^^^^^^^^^^^^
  File "C:\Users\daksh\AppData\Local\Programs\Python\Python313\Lib\site-packages\aiohttp\connector.py", line 1013, in _resolve_host
    return await asyncio.shield(resolved_host_task)
           ^^^^^^^^^^^^^^^^^^^^^^^^^^^^^^^^^^^^^^^^
  File "C:\Users\daksh\AppData\Local\Programs\Python\Python313\Lib\site-packages\aiohttp\connector.py", line 1044, in _resolve_host_with_throttle
    addrs = await self._resolver.resolve(host, port, family=self._family)
            ^^^^^^^^^^^^^^^^^^^^^^^^^^^^^^^^^^^^^^^^^^^^^^^^^^^^^^^^^^^^^
  File "C:\Users\daksh\AppData\Local\Programs\Python\Python313\Lib\site-packages\aiohttp\resolver.py", line 40, in resolve
    infos = await self._loop.getaddrinfo(
            ^^^^^^^^^^^^^^^^^^^^^^^^^^^^^
    ...<5 lines>...
    )
    ^
  File "C:\Users\daksh\AppData\Local\Programs\Python\Python313\Lib\asyncio\base_events.py", line 933, in getaddrinfo
    return await self.run_in_executor(
           ^^^^^^^^^^^^^^^^^^^^^^^^^^^
        None, getaddr_func, host, port, family, type, proto, flags)
        ^^^^^^^^^^^^^^^^^^^^^^^^^^^^^^^^^^^^^^^^^^^^^^^^^^^^^^^^^^^
  File "C:\Users\daksh\AppData\Local\Programs\Python\Python313\Lib\concurrent\futures\thread.py", line 59, in run
    result = self.fn(*self.args, **self.kwargs)
  File "C:\Users\daksh\AppData\Local\Programs\Python\Python313\Lib\socket.py", line 977, in getaddrinfo
    for res in _socket.getaddrinfo(host, port, family, type, proto, flags):
               ~~~~~~~~~~~~~~~~~~~^^^^^^^^^^^^^^^^^^^^^^^^^^^^^^^^^^^^^^^^
socket.gaierror: [Errno 11001] getaddrinfo failed

The above exception was the direct cause of the following exception:

Traceback (most recent call last):
  File "C:\Users\daksh\AppData\Local\Programs\Python\Python313\Lib\site-packages\discord\client.py", line 701, in connect
    self.ws = await asyncio.wait_for(coro, timeout=60.0)
              ^^^^^^^^^^^^^^^^^^^^^^^^^^^^^^^^^^^^^^^^^^
  File "C:\Users\daksh\AppData\Local\Programs\Python\Python313\Lib\asyncio\tasks.py", line 507, in wait_for
    return await fut
           ^^^^^^^^^
  File "C:\Users\daksh\AppData\Local\Programs\Python\Python313\Lib\site-packages\discord\gateway.py", line 375, in from_client
    socket = await client.http.ws_connect(str(url))
             ^^^^^^^^^^^^^^^^^^^^^^^^^^^^^^^^^^^^^^
  File "C:\Users\daksh\AppData\Local\Programs\Python\Python313\Lib\site-packages\discord\http.py", line 554, in ws_connect
    return await self.__session.ws_connect(url, **kwargs)
           ^^^^^^^^^^^^^^^^^^^^^^^^^^^^^^^^^^^^^^^^^^^^^^
  File "C:\Users\daksh\AppData\Local\Programs\Python\Python313\Lib\site-packages\aiohttp\client.py", line 1036, in _ws_connect
    resp = await self.request(
           ^^^^^^^^^^^^^^^^^^^
    ...<11 lines>...
    )
    ^
  File "C:\Users\daksh\AppData\Local\Programs\Python\Python313\Lib\site-packages\aiohttp\client.py", line 760, in _request
    resp = await handler(req)
           ^^^^^^^^^^^^^^^^^^
  File "C:\Users\daksh\AppData\Local\Programs\Python\Python313\Lib\site-packages\aiohttp\client.py", line 715, in _connect_and_send_request
    conn = await self._connector.connect(
           ^^^^^^^^^^^^^^^^^^^^^^^^^^^^^^
        req, traces=traces, timeout=real_timeout
        ^^^^^^^^^^^^^^^^^^^^^^^^^^^^^^^^^^^^^^^^
    )
    ^
  File "C:\Users\daksh\AppData\Local\Programs\Python\Python313\Lib\site-packages\aiohttp\connector.py", line 561, in connect
    proto = await self._create_connection(req, traces, timeout)
            ^^^^^^^^^^^^^^^^^^^^^^^^^^^^^^^^^^^^^^^^^^^^^^^^^^^
  File "C:\Users\daksh\AppData\Local\Programs\Python\Python313\Lib\site-packages\aiohttp\connector.py", line 1074, in _create_connection
    _, proto = await self._create_direct_connection(req, traces, timeout)
               ^^^^^^^^^^^^^^^^^^^^^^^^^^^^^^^^^^^^^^^^^^^^^^^^^^^^^^^^^^
  File "C:\Users\daksh\AppData\Local\Programs\Python\Python313\Lib\site-packages\aiohttp\connector.py", line 1382, in _create_direct_connection
    raise ClientConnectorDNSError(req.connection_key, exc) from exc
aiohttp.client_exceptions.ClientConnectorDNSError: Cannot connect to host gateway-us-east1-c.discord.gg:443 ssl:default [getaddrinfo failed]
2025-06-26 11:32:12,745 - discord.client - ERROR - Attempting a reconnect in 0.53s
Traceback (most recent call last):
  File "C:\Users\daksh\AppData\Local\Programs\Python\Python313\Lib\site-packages\aiohttp\connector.py", line 1376, in _create_direct_connection
    hosts = await self._resolve_host(host, port, traces=traces)
            ^^^^^^^^^^^^^^^^^^^^^^^^^^^^^^^^^^^^^^^^^^^^^^^^^^^
  File "C:\Users\daksh\AppData\Local\Programs\Python\Python313\Lib\site-packages\aiohttp\connector.py", line 1013, in _resolve_host
    return await asyncio.shield(resolved_host_task)
           ^^^^^^^^^^^^^^^^^^^^^^^^^^^^^^^^^^^^^^^^
  File "C:\Users\daksh\AppData\Local\Programs\Python\Python313\Lib\site-packages\aiohttp\connector.py", line 1044, in _resolve_host_with_throttle
    addrs = await self._resolver.resolve(host, port, family=self._family)
            ^^^^^^^^^^^^^^^^^^^^^^^^^^^^^^^^^^^^^^^^^^^^^^^^^^^^^^^^^^^^^
  File "C:\Users\daksh\AppData\Local\Programs\Python\Python313\Lib\site-packages\aiohttp\resolver.py", line 40, in resolve
    infos = await self._loop.getaddrinfo(
            ^^^^^^^^^^^^^^^^^^^^^^^^^^^^^
    ...<5 lines>...
    )
    ^
  File "C:\Users\daksh\AppData\Local\Programs\Python\Python313\Lib\asyncio\base_events.py", line 933, in getaddrinfo
    return await self.run_in_executor(
           ^^^^^^^^^^^^^^^^^^^^^^^^^^^
        None, getaddr_func, host, port, family, type, proto, flags)
        ^^^^^^^^^^^^^^^^^^^^^^^^^^^^^^^^^^^^^^^^^^^^^^^^^^^^^^^^^^^
  File "C:\Users\daksh\AppData\Local\Programs\Python\Python313\Lib\concurrent\futures\thread.py", line 59, in run
    result = self.fn(*self.args, **self.kwargs)
  File "C:\Users\daksh\AppData\Local\Programs\Python\Python313\Lib\socket.py", line 977, in getaddrinfo
    for res in _socket.getaddrinfo(host, port, family, type, proto, flags):
               ~~~~~~~~~~~~~~~~~~~^^^^^^^^^^^^^^^^^^^^^^^^^^^^^^^^^^^^^^^^
socket.gaierror: [Errno 11001] getaddrinfo failed

The above exception was the direct cause of the following exception:

Traceback (most recent call last):
  File "C:\Users\daksh\AppData\Local\Programs\Python\Python313\Lib\site-packages\discord\client.py", line 701, in connect
    self.ws = await asyncio.wait_for(coro, timeout=60.0)
              ^^^^^^^^^^^^^^^^^^^^^^^^^^^^^^^^^^^^^^^^^^
  File "C:\Users\daksh\AppData\Local\Programs\Python\Python313\Lib\asyncio\tasks.py", line 507, in wait_for
    return await fut
           ^^^^^^^^^
  File "C:\Users\daksh\AppData\Local\Programs\Python\Python313\Lib\site-packages\discord\gateway.py", line 375, in from_client
    socket = await client.http.ws_connect(str(url))
             ^^^^^^^^^^^^^^^^^^^^^^^^^^^^^^^^^^^^^^
  File "C:\Users\daksh\AppData\Local\Programs\Python\Python313\Lib\site-packages\discord\http.py", line 554, in ws_connect
    return await self.__session.ws_connect(url, **kwargs)
           ^^^^^^^^^^^^^^^^^^^^^^^^^^^^^^^^^^^^^^^^^^^^^^
  File "C:\Users\daksh\AppData\Local\Programs\Python\Python313\Lib\site-packages\aiohttp\client.py", line 1036, in _ws_connect
    resp = await self.request(
           ^^^^^^^^^^^^^^^^^^^
    ...<11 lines>...
    )
    ^
  File "C:\Users\daksh\AppData\Local\Programs\Python\Python313\Lib\site-packages\aiohttp\client.py", line 760, in _request
    resp = await handler(req)
           ^^^^^^^^^^^^^^^^^^
  File "C:\Users\daksh\AppData\Local\Programs\Python\Python313\Lib\site-packages\aiohttp\client.py", line 715, in _connect_and_send_request
    conn = await self._connector.connect(
           ^^^^^^^^^^^^^^^^^^^^^^^^^^^^^^
        req, traces=traces, timeout=real_timeout
        ^^^^^^^^^^^^^^^^^^^^^^^^^^^^^^^^^^^^^^^^
    )
    ^
  File "C:\Users\daksh\AppData\Local\Programs\Python\Python313\Lib\site-packages\aiohttp\connector.py", line 561, in connect
    proto = await self._create_connection(req, traces, timeout)
            ^^^^^^^^^^^^^^^^^^^^^^^^^^^^^^^^^^^^^^^^^^^^^^^^^^^
  File "C:\Users\daksh\AppData\Local\Programs\Python\Python313\Lib\site-packages\aiohttp\connector.py", line 1074, in _create_connection
    _, proto = await self._create_direct_connection(req, traces, timeout)
               ^^^^^^^^^^^^^^^^^^^^^^^^^^^^^^^^^^^^^^^^^^^^^^^^^^^^^^^^^^
  File "C:\Users\daksh\AppData\Local\Programs\Python\Python313\Lib\site-packages\aiohttp\connector.py", line 1382, in _create_direct_connection
    raise ClientConnectorDNSError(req.connection_key, exc) from exc
aiohttp.client_exceptions.ClientConnectorDNSError: Cannot connect to host gateway-us-east1-c.discord.gg:443 ssl:default [getaddrinfo failed]
2025-06-26 11:32:13,289 - discord.client - ERROR - Attempting a reconnect in 7.60s
Traceback (most recent call last):
  File "C:\Users\daksh\AppData\Local\Programs\Python\Python313\Lib\site-packages\aiohttp\connector.py", line 1376, in _create_direct_connection
    hosts = await self._resolve_host(host, port, traces=traces)
            ^^^^^^^^^^^^^^^^^^^^^^^^^^^^^^^^^^^^^^^^^^^^^^^^^^^
  File "C:\Users\daksh\AppData\Local\Programs\Python\Python313\Lib\site-packages\aiohttp\connector.py", line 1013, in _resolve_host
    return await asyncio.shield(resolved_host_task)
           ^^^^^^^^^^^^^^^^^^^^^^^^^^^^^^^^^^^^^^^^
  File "C:\Users\daksh\AppData\Local\Programs\Python\Python313\Lib\site-packages\aiohttp\connector.py", line 1044, in _resolve_host_with_throttle
    addrs = await self._resolver.resolve(host, port, family=self._family)
            ^^^^^^^^^^^^^^^^^^^^^^^^^^^^^^^^^^^^^^^^^^^^^^^^^^^^^^^^^^^^^
  File "C:\Users\daksh\AppData\Local\Programs\Python\Python313\Lib\site-packages\aiohttp\resolver.py", line 40, in resolve
    infos = await self._loop.getaddrinfo(
            ^^^^^^^^^^^^^^^^^^^^^^^^^^^^^
    ...<5 lines>...
    )
    ^
  File "C:\Users\daksh\AppData\Local\Programs\Python\Python313\Lib\asyncio\base_events.py", line 933, in getaddrinfo
    return await self.run_in_executor(
           ^^^^^^^^^^^^^^^^^^^^^^^^^^^
        None, getaddr_func, host, port, family, type, proto, flags)
        ^^^^^^^^^^^^^^^^^^^^^^^^^^^^^^^^^^^^^^^^^^^^^^^^^^^^^^^^^^^
  File "C:\Users\daksh\AppData\Local\Programs\Python\Python313\Lib\concurrent\futures\thread.py", line 59, in run
    result = self.fn(*self.args, **self.kwargs)
  File "C:\Users\daksh\AppData\Local\Programs\Python\Python313\Lib\socket.py", line 977, in getaddrinfo
    for res in _socket.getaddrinfo(host, port, family, type, proto, flags):
               ~~~~~~~~~~~~~~~~~~~^^^^^^^^^^^^^^^^^^^^^^^^^^^^^^^^^^^^^^^^
socket.gaierror: [Errno 11001] getaddrinfo failed

The above exception was the direct cause of the following exception:

Traceback (most recent call last):
  File "C:\Users\daksh\AppData\Local\Programs\Python\Python313\Lib\site-packages\discord\client.py", line 701, in connect
    self.ws = await asyncio.wait_for(coro, timeout=60.0)
              ^^^^^^^^^^^^^^^^^^^^^^^^^^^^^^^^^^^^^^^^^^
  File "C:\Users\daksh\AppData\Local\Programs\Python\Python313\Lib\asyncio\tasks.py", line 507, in wait_for
    return await fut
           ^^^^^^^^^
  File "C:\Users\daksh\AppData\Local\Programs\Python\Python313\Lib\site-packages\discord\gateway.py", line 375, in from_client
    socket = await client.http.ws_connect(str(url))
             ^^^^^^^^^^^^^^^^^^^^^^^^^^^^^^^^^^^^^^
  File "C:\Users\daksh\AppData\Local\Programs\Python\Python313\Lib\site-packages\discord\http.py", line 554, in ws_connect
    return await self.__session.ws_connect(url, **kwargs)
           ^^^^^^^^^^^^^^^^^^^^^^^^^^^^^^^^^^^^^^^^^^^^^^
  File "C:\Users\daksh\AppData\Local\Programs\Python\Python313\Lib\site-packages\aiohttp\client.py", line 1036, in _ws_connect
    resp = await self.request(
           ^^^^^^^^^^^^^^^^^^^
    ...<11 lines>...
    )
    ^
  File "C:\Users\daksh\AppData\Local\Programs\Python\Python313\Lib\site-packages\aiohttp\client.py", line 760, in _request
    resp = await handler(req)
           ^^^^^^^^^^^^^^^^^^
  File "C:\Users\daksh\AppData\Local\Programs\Python\Python313\Lib\site-packages\aiohttp\client.py", line 715, in _connect_and_send_request
    conn = await self._connector.connect(
           ^^^^^^^^^^^^^^^^^^^^^^^^^^^^^^
        req, traces=traces, timeout=real_timeout
        ^^^^^^^^^^^^^^^^^^^^^^^^^^^^^^^^^^^^^^^^
    )
    ^
  File "C:\Users\daksh\AppData\Local\Programs\Python\Python313\Lib\site-packages\aiohttp\connector.py", line 561, in connect
    proto = await self._create_connection(req, traces, timeout)
            ^^^^^^^^^^^^^^^^^^^^^^^^^^^^^^^^^^^^^^^^^^^^^^^^^^^
  File "C:\Users\daksh\AppData\Local\Programs\Python\Python313\Lib\site-packages\aiohttp\connector.py", line 1074, in _create_connection
    _, proto = await self._create_direct_connection(req, traces, timeout)
               ^^^^^^^^^^^^^^^^^^^^^^^^^^^^^^^^^^^^^^^^^^^^^^^^^^^^^^^^^^
  File "C:\Users\daksh\AppData\Local\Programs\Python\Python313\Lib\site-packages\aiohttp\connector.py", line 1382, in _create_direct_connection
    raise ClientConnectorDNSError(req.connection_key, exc) from exc
aiohttp.client_exceptions.ClientConnectorDNSError: Cannot connect to host gateway-us-east1-c.discord.gg:443 ssl:default [getaddrinfo failed]
2025-06-26 11:32:20,911 - discord.client - ERROR - Attempting a reconnect in 5.89s
Traceback (most recent call last):
  File "C:\Users\daksh\AppData\Local\Programs\Python\Python313\Lib\site-packages\aiohttp\connector.py", line 1376, in _create_direct_connection
    hosts = await self._resolve_host(host, port, traces=traces)
            ^^^^^^^^^^^^^^^^^^^^^^^^^^^^^^^^^^^^^^^^^^^^^^^^^^^
  File "C:\Users\daksh\AppData\Local\Programs\Python\Python313\Lib\site-packages\aiohttp\connector.py", line 1013, in _resolve_host
    return await asyncio.shield(resolved_host_task)
           ^^^^^^^^^^^^^^^^^^^^^^^^^^^^^^^^^^^^^^^^
  File "C:\Users\daksh\AppData\Local\Programs\Python\Python313\Lib\site-packages\aiohttp\connector.py", line 1044, in _resolve_host_with_throttle
    addrs = await self._resolver.resolve(host, port, family=self._family)
            ^^^^^^^^^^^^^^^^^^^^^^^^^^^^^^^^^^^^^^^^^^^^^^^^^^^^^^^^^^^^^
  File "C:\Users\daksh\AppData\Local\Programs\Python\Python313\Lib\site-packages\aiohttp\resolver.py", line 40, in resolve
    infos = await self._loop.getaddrinfo(
            ^^^^^^^^^^^^^^^^^^^^^^^^^^^^^
    ...<5 lines>...
    )
    ^
  File "C:\Users\daksh\AppData\Local\Programs\Python\Python313\Lib\asyncio\base_events.py", line 933, in getaddrinfo
    return await self.run_in_executor(
           ^^^^^^^^^^^^^^^^^^^^^^^^^^^
        None, getaddr_func, host, port, family, type, proto, flags)
        ^^^^^^^^^^^^^^^^^^^^^^^^^^^^^^^^^^^^^^^^^^^^^^^^^^^^^^^^^^^
  File "C:\Users\daksh\AppData\Local\Programs\Python\Python313\Lib\concurrent\futures\thread.py", line 59, in run
    result = self.fn(*self.args, **self.kwargs)
  File "C:\Users\daksh\AppData\Local\Programs\Python\Python313\Lib\socket.py", line 977, in getaddrinfo
    for res in _socket.getaddrinfo(host, port, family, type, proto, flags):
               ~~~~~~~~~~~~~~~~~~~^^^^^^^^^^^^^^^^^^^^^^^^^^^^^^^^^^^^^^^^
socket.gaierror: [Errno 11001] getaddrinfo failed

The above exception was the direct cause of the following exception:

Traceback (most recent call last):
  File "C:\Users\daksh\AppData\Local\Programs\Python\Python313\Lib\site-packages\discord\client.py", line 701, in connect
    self.ws = await asyncio.wait_for(coro, timeout=60.0)
              ^^^^^^^^^^^^^^^^^^^^^^^^^^^^^^^^^^^^^^^^^^
  File "C:\Users\daksh\AppData\Local\Programs\Python\Python313\Lib\asyncio\tasks.py", line 507, in wait_for
    return await fut
           ^^^^^^^^^
  File "C:\Users\daksh\AppData\Local\Programs\Python\Python313\Lib\site-packages\discord\gateway.py", line 375, in from_client
    socket = await client.http.ws_connect(str(url))
             ^^^^^^^^^^^^^^^^^^^^^^^^^^^^^^^^^^^^^^
  File "C:\Users\daksh\AppData\Local\Programs\Python\Python313\Lib\site-packages\discord\http.py", line 554, in ws_connect
    return await self.__session.ws_connect(url, **kwargs)
           ^^^^^^^^^^^^^^^^^^^^^^^^^^^^^^^^^^^^^^^^^^^^^^
  File "C:\Users\daksh\AppData\Local\Programs\Python\Python313\Lib\site-packages\aiohttp\client.py", line 1036, in _ws_connect
    resp = await self.request(
           ^^^^^^^^^^^^^^^^^^^
    ...<11 lines>...
    )
    ^
  File "C:\Users\daksh\AppData\Local\Programs\Python\Python313\Lib\site-packages\aiohttp\client.py", line 760, in _request
    resp = await handler(req)
           ^^^^^^^^^^^^^^^^^^
  File "C:\Users\daksh\AppData\Local\Programs\Python\Python313\Lib\site-packages\aiohttp\client.py", line 715, in _connect_and_send_request
    conn = await self._connector.connect(
           ^^^^^^^^^^^^^^^^^^^^^^^^^^^^^^
        req, traces=traces, timeout=real_timeout
        ^^^^^^^^^^^^^^^^^^^^^^^^^^^^^^^^^^^^^^^^
    )
    ^
  File "C:\Users\daksh\AppData\Local\Programs\Python\Python313\Lib\site-packages\aiohttp\connector.py", line 561, in connect
    proto = await self._create_connection(req, traces, timeout)
            ^^^^^^^^^^^^^^^^^^^^^^^^^^^^^^^^^^^^^^^^^^^^^^^^^^^
  File "C:\Users\daksh\AppData\Local\Programs\Python\Python313\Lib\site-packages\aiohttp\connector.py", line 1074, in _create_connection
    _, proto = await self._create_direct_connection(req, traces, timeout)
               ^^^^^^^^^^^^^^^^^^^^^^^^^^^^^^^^^^^^^^^^^^^^^^^^^^^^^^^^^^
  File "C:\Users\daksh\AppData\Local\Programs\Python\Python313\Lib\site-packages\aiohttp\connector.py", line 1382, in _create_direct_connection
    raise ClientConnectorDNSError(req.connection_key, exc) from exc
aiohttp.client_exceptions.ClientConnectorDNSError: Cannot connect to host gateway-us-east1-c.discord.gg:443 ssl:default [getaddrinfo failed]
2025-06-26 11:32:27,748 - discord.gateway - INFO - Shard ID None session has been invalidated.
2025-06-26 11:32:34,060 - discord.gateway - INFO - Shard ID None has connected to Gateway (Session ID: fb39f3f6bd56552b9ef390fbfc7c089e).
2025-06-26 12:25:10,027 - discord.gateway - INFO - Shard ID None has successfully RESUMED session fb39f3f6bd56552b9ef390fbfc7c089e.
2025-06-26 13:36:43,894 - discord.gateway - INFO - Shard ID None session has been invalidated.
